#VRML_SIM R2022a utf8
WorldInfo {
  basicTimeStep 32
}
Viewpoint {
  orientation -0.35953456238438164 0.6073211814892773 0.7084461030773898 1.2891326700969095
  position -7.261815188895315 -10.967526705436937 17.49463290577502
  follow "lilbot"
}
TexturedBackground {
}
TexturedBackgroundLight {
}
Robot {
  translation 0 0 0.02
  children [
    Transform {
      children [
        Lidar {
          translation 0 0 0.09
          rotation 0 0 1 3.14159265359
          horizontalResolution 360
          fieldOfView 6.28319
          numberOfLayers 1
          minRange 0.12
          maxRange 8
          type "fixed"
          noise 0.00001
          resolution 0.96
          defaultFrequency 8
          minFrequency 5
          maxFrequency 8
        }
      ]
    }
    BallJoint {
      jointParameters BallJointParameters {
        anchor 0.0625 0 -0.0075
        staticFriction 0.5
      }
      jointParameters2 JointParameters {
        axis 1 0 0
        staticFriction 0.5
      }
      jointParameters3 JointParameters {
        axis 0 1 0
        staticFriction 0.5
      }
      endPoint Solid {
        translation 0.0625 0 -0.0075
        children [
          Transform {
            children [
              DEF BALL Shape {
                appearance PBRAppearance {
                }
                geometry Mesh {
                  url [
                    "../meshes/models/caster_ball.obj"
                  ]
                }
              }
            ]
          }
        ]
        name "caster_ball_front"
        boundingObject Transform {
          children [
            USE BALL
          ]
        }
        physics Physics {
        }
      }
    }
    BallJoint {
      jointParameters BallJointParameters {
        anchor -0.0625 0 -0.0075
        staticFriction 0.5
      }
      jointParameters2 JointParameters {
        axis 1 0 0
        staticFriction 0.5
      }
      jointParameters3 JointParameters {
        axis 0 1 0
        staticFriction 0.5
      }
      endPoint Solid {
        translation -0.0625 0 -0.0075
        children [
          Transform {
            children [
              DEF BALL Shape {
                appearance PBRAppearance {
                }
                geometry Mesh {
                  url [
                    "../meshes/models/caster_ball.obj"
                  ]
                }
              }
            ]
          }
        ]
        boundingObject Transform {
          children [
            USE BALL
          ]
        }
        physics Physics {
        }
      }
    }
    Transform {
      children [
        DEF BODY Shape {
          appearance PBRAppearance {
            metalness 0
          }
          geometry Mesh {
            url [
              "../meshes/models/body.obj"
            ]
          }
        }
      ]
    }
    HingeJoint {
      jointParameters HingeJointParameters {
        axis 0 1 0
        anchor 0 0.0925 0.0225
      }
      device [
        PositionSensor {
          name "encoder_wheel_left"
          noise 0.001
          resolution 0.00670421
        }
        RotationalMotor {
          name "motor_wheel_left"
        }
      ]
      endPoint Solid {
        translation 0 0.094 0.0225
        rotation 0 0 1 3.139727936715174
        children [
          Transform {
            children [
              Shape {
                appearance PBRAppearance {
                  baseColor 0.1 0.1 0.5
                  roughness 1
                  metalness 0
                }
                geometry Mesh {
                  url [
                    "../meshes/models/wheel.obj"
                  ]
                }
              }
            ]
          }
        ]
        name "wheel_left"
        boundingObject Transform {
          translation 0 -0.0125 0
          rotation 1 0 0 1.5708
          children [
            Shape {
              geometry Cylinder {
                height 0.025
                radius 0.038
              }
            }
          ]
        }
        physics Physics {
        }
      }
    }
    HingeJoint {
      jointParameters HingeJointParameters {
        axis 0 1 0
        anchor 0 -0.0925 0.0225
      }
      device [
        PositionSensor {
          name "encoder_wheel_right"
          noise 0.001
          resolution 0.00670421
        }
        RotationalMotor {
          name "motor_wheel_right"
        }
      ]
      endPoint Solid {
        translation 0 -0.094 0.0225
        rotation 0 1 0 0
        children [
          Transform {
            children [
              DEF WHEEL Shape {
                appearance PBRAppearance {
                  baseColor 0.1 0.1 0.5
                  roughness 1
                  metalness 0
                }
                geometry Mesh {
                  url [
                    "../meshes/models/wheel.obj"
                  ]
                }
              }
            ]
          }
        ]
        name "wheel_right"
        boundingObject Transform {
          translation 0 -0.0125 0
          rotation 1 0 0 1.5708
          children [
            Shape {
              geometry Cylinder {
                height 0.025
                radius 0.038
              }
            }
          ]
        }
        physics Physics {
        }
      }
    }
  ]
  name "lilbot"
  boundingObject Transform {
    children [
      USE BODY
    ]
  }
  physics Physics {
    centerOfMass [
      -0.01 0 0.02
    ]
  }
  controller "<extern>"
}
Floor {
  tileSize 2 2
}
OilBarrel {
  translation 1.09 1.05 0.44
}
OilBarrel {
  translation 1.09 -1.1 0.44
  name "oil barrel(1)"
}
OilBarrel {
  translation 0.07 0.72 0.44
  name "oil barrel(2)"
}
OilBarrel {
  translation -1.58 -0.81 0.44
  name "oil barrel(3)"
}
Wall {
  translation -5 0 0
  size 0.2 10 2.4
}
Wall {
  translation 5 0 0
  name "wall(1)"
  size 0.2 10 2.4
}
Wall {
  translation 0 -5 0
  rotation 0 0 1 1.5708
  name "wall(2)"
  size 0.2 10 2.4
}
Wall {
  translation 0 5 0
  rotation 0 0 1 1.5708
  name "wall(3)"
  size 0.2 10 2.4
}
