#VRML_SIM R2022a utf8
WorldInfo {
}
Viewpoint {
  orientation 0.07398494468266215 0.05133582511379848 -0.9959371772457281 1.9321672262211267
  position 0.5809572347797467 1.4437973953342589 0.3028142324915225
}
TexturedBackground {
}
TexturedBackgroundLight {
}
RectangleArena {
  floorSize 10 10
  wallHeight 0.4
}
Solid {
  translation -1.98 0.82 0.25
  children [
    DEF CUBE Shape {
      appearance OldPlywood {
      }
      geometry Box {
        size 0.5 0.5 0.5
      }
    }
  ]
  name "solid(3)"
  boundingObject USE CUBE
}
Solid {
  translation 2.58 0.52 0.25
  children [
    DEF CUBE Shape {
      appearance OldPlywood {
      }
      geometry Box {
        size 0.5 0.5 0.5
      }
    }
  ]
  name "solid(1)"
  boundingObject USE CUBE
  locked TRUE
}
Solid {
  translation -0.01 -1.5 0.25
  rotation 0 0 1 -0.785395307179586
  children [
    DEF CUBE Shape {
      appearance OldPlywood {
      }
      geometry Box {
        size 0.5 0.5 0.5
      }
    }
  ]
  name "solid(2)"
  boundingObject USE CUBE
}
Robot {
  translation 0 0 0.02
  children [
    Transform {
      children [
        Lidar {
          translation 0 0 0.09
          horizontalResolution 360
          fieldOfView 6.28319
          numberOfLayers 1
          minRange 0.12
          maxRange 8
          type "rotating"
          noise 0.0002
          resolution 0.96
          defaultFrequency 6
          minFrequency 5
          maxFrequency 8
        }
      ]
    }
    BallJoint {
      jointParameters BallJointParameters {
        anchor 0.0625 0 -0.007
        staticFriction 0.5
      }
      jointParameters2 JointParameters {
        position 6
        axis 1 0 0
        staticFriction 0.5
      }
      jointParameters3 JointParameters {
        position 4
        axis 0 1 0
        staticFriction 0.5
      }
      endPoint Solid {
        translation 0.0625 0 -0.007
        rotation 0.6206770577731384 -0.7724015429693032 0.13474363203031084 1.4474786929076553
        children [
          Transform {
            scale 0.001 0.001 0.001
            children [
              DEF BALL Shape {
                appearance PBRAppearance {
                }
                geometry Mesh {
                  url [
                    "/home/jeffrey/ros2_dev_ws/src/little_bot/lilbot_webot_sim/meshes/caster_ball.obj"
                  ]
                }
              }
            ]
          }
        ]
        name "solid_ball1"
        boundingObject Transform {
          scale 0.001 0.001 0.001
          children [
            USE BALL
          ]
        }
        physics Physics {
          density -1
          mass 0.001712399027485384
          centerOfMass [
            0.06262883775752591 -8.785614601863485e-05 0.03511871005705902
          ]
          inertiaMatrix [
            4.261628193482875e-06 1.769492973579715e-05 1.3471112457798882e-05
            1.8802335278549203e-08 -7.532643258323707e-06 1.0575276392812056e-08
          ]
        }
      }
    }
    BallJoint {
      jointParameters BallJointParameters {
        anchor -0.0625 0 -0.007
        staticFriction 0.5
      }
      jointParameters2 JointParameters {
        axis 1 0 0
        staticFriction 0.5
      }
      jointParameters3 JointParameters {
        axis 0 1 0
        staticFriction 0.5
      }
      endPoint Solid {
        translation -0.0625 0 -0.007
        rotation -0.18276343630023836 -0.9548142921377932 -0.23436551342109463 1.3948451352912825
        children [
          Transform {
            scale 0.001 0.001 0.001
            children [
              DEF BALL Shape {
                appearance PBRAppearance {
                }
                geometry Mesh {
                  url [
                    "/home/jeffrey/ros2_dev_ws/src/little_bot/lilbot_webot_sim/meshes/caster_ball.obj"
                  ]
                }
              }
            ]
          }
        ]
        boundingObject Transform {
          scale 0.001 0.001 0.001
          children [
            USE BALL
          ]
        }
        physics Physics {
          density -1
          mass 0.0017123990274853951
          centerOfMass [
            -0.062389080969379423 -1.1814375581929792e-05 0.0348078137894857
          ]
          inertiaMatrix [
            4.187118506578838e-06 1.7517851935708023e-05 1.3368429456574648e-05
            -2.496103080667009e-09 7.437402773296591e-06 1.4015020393253558e-09
          ]
        }
      }
    }
    Transform {
      scale 0.001 0.001 0.001
      children [
        DEF BODY Shape {
          appearance PBRAppearance {
            metalness 0
          }
          geometry Mesh {
            url [
              "/home/jeffrey/ros2_dev_ws/src/little_bot/lilbot_webot_sim/meshes/body.obj"
            ]
          }
        }
      ]
    }
    HingeJoint {
      jointParameters HingeJointParameters {
        axis 0 1 0
        anchor 0 0.0925 0.0225
        staticFriction 0.1
      }
      device [
        PositionSensor {
          name "left_wheel_encoder"
          noise 0.001
          resolution 0.00670421
        }
        RotationalMotor {
          name "left_wheel_motor"
        }
      ]
      endPoint Solid {
        translation 0 0.094 0.0225
        rotation 0 0 1 3.139727936715174
        children [
          Transform {
            scale 0.001 0.001 0.001
            children [
              Shape {
                appearance PBRAppearance {
                  baseColor 0.1 0.1 0.5
                  roughness 1
                  metalness 0
                }
                geometry Mesh {
                  url [
                    "/home/jeffrey/ros2_dev_ws/src/little_bot/lilbot_webot_sim/meshes/wheel.obj"
                  ]
                }
              }
            ]
          }
        ]
        name "solid(2)"
        boundingObject Transform {
          translation 0 -0.0125 0
          rotation 1 0 0 1.5708
          children [
            Shape {
              geometry Cylinder {
                height 0.025
                radius 0.038
              }
            }
          ]
        }
        physics Physics {
          density -1
          mass 0.11341149479459153
          centerOfMass [
            0 -0.0125 0
          ]
          inertiaMatrix [
            6.456894436972078e-05 8.188309924122239e-05 6.456894437019349e-05
            0 0 1.286896422574151e-10
          ]
        }
      }
    }
    HingeJoint {
      jointParameters HingeJointParameters {
        axis 0 1 0
        anchor 0 -0.0925 0.0225
        staticFriction 0.1
      }
      device [
        PositionSensor {
          name "right_wheel_encoder"
          noise 0.001
          resolution 0.00670421
        }
        RotationalMotor {
          name "right_wheel_motor"
        }
      ]
      endPoint Solid {
        translation 0 -0.094 0.0225
        rotation 0 1 0 2.9964074639928517
        children [
          Transform {
            scale 0.001 0.001 0.001
            children [
              DEF WHEEL Shape {
                appearance PBRAppearance {
                  baseColor 0.1 0.1 0.5
                  roughness 1
                  metalness 0
                }
                geometry Mesh {
                  url [
                    "/home/jeffrey/ros2_dev_ws/src/little_bot/lilbot_webot_sim/meshes/wheel.obj"
                  ]
                }
              }
            ]
          }
        ]
        name "solid(3)"
        boundingObject Transform {
          translation 0 -0.0125 0
          rotation 1 0 0 1.5708
          children [
            Shape {
              geometry Cylinder {
                height 0.025
                radius 0.038
              }
            }
          ]
        }
        physics Physics {
          density -1
          mass 0.11341149479459153
          centerOfMass [
            0 -0.0125 0
          ]
          inertiaMatrix [
            6.456894436972078e-05 8.188309924122239e-05 6.456894437019349e-05
            0 0 1.286896422574151e-10
          ]
        }
      }
    }
  ]
  boundingObject Transform {
    scale 0.001 0.001 0.001
    children [
      USE BODY
    ]
  }
  physics Physics {
    density -1
    mass 0.911
    centerOfMass [
      -0.02 0 0.02
    ]
    inertiaMatrix [
      0.013844221486827058 0.01391185483699126 0.005019288674587349
      1.8522959928894904e-07 0.00016054266409879994 2.7691660684257923e-06
    ]
  }
  controller "ros"
}
