#VRML_SIM R2022a utf8
WorldInfo {
}
Viewpoint {
  orientation -0.29371739980682676 -0.11028911374888005 0.9495085046692332 3.82656164350981
  position 1.6027753276927965 1.3565935107989928 1.3693288548203095
}
TexturedBackground {
}
TexturedBackgroundLight {
}
CircleArena {
}
Robot {
  translation 0 0 0.04
  children [
    Transform {
      children [
          Lidar {
              translation 0 0 0.09
              horizontalResolution 360
              fieldOfView 6.28319
              numberOfLayers 1
              minRange 0.12
              maxRange 8
              type "rotating"
              noise 0.0002
              resolution 0.96
              defaultFrequency 6
              minFrequency 5
              maxFrequency 8
          }
      ]
    }
    BallJoint {
        jointParameters BallJointParameters {
            anchor 0.0625 0 -0.006
            staticFriction 0.5
        }
        jointParameters2 JointParameters {
            axis 1 0 0
            staticFriction 0.5
        }
        jointParameters3 JointParameters {
            axis 0 1 0
            staticFriction 0.5
        }
        endPoint Solid {
            translation 0.0625 0 -0.006
            children [
                Transform {
                    scale 0.001 0.001 0.001
                    children [
                        DEF BALL Shape {
                            appearance PBRAppearance { }
                            geometry Mesh { url [
                              "../meshes/caster_ball.obj"
                            ] }
                        }
                    ]
                }
            ]
            name "caster_ball_front"
            boundingObject Transform {
                scale 0.001 0.001 0.001
                children [ USE BALL ]
            }
            physics Physics { }
        }
    }
    BallJoint {
        jointParameters BallJointParameters {
            anchor -0.0625 0 -0.006
            staticFriction 0.5
        }
        jointParameters2 JointParameters {
            axis 1 0 0
            staticFriction 0.5
        }
        jointParameters3 JointParameters {
            axis 0 1 0
            staticFriction 0.5
        }
        endPoint Solid {
            translation -0.0625 0 -0.006
            children [
                Transform {
                    scale 0.001 0.001 0.001
                    children [
                        DEF BALL Shape {
                            appearance PBRAppearance { }
                            geometry Mesh { url [
                              "../meshes/caster_ball.obj"
                            ] }
                        }
                    ]
                }
            ]
            boundingObject Transform {
                scale 0.001 0.001 0.001
                children [ USE BALL ]
            }
            physics Physics { }
        }
    }
    Transform {
      scale 0.001 0.001 0.001
      children [
        DEF BODY Shape {
          appearance PBRAppearance {
            metalness 0
          }
          geometry Mesh {
            url [
              "../meshes/body.obj"
            ]
          }
        }
      ]
    }
    HingeJoint {
      jointParameters HingeJointParameters {
        axis 0 1 0
        anchor 0 0.0925 0.0225
      }
      device [
        PositionSensor {
          name "encoder_wheel_left"
          noise 0.001
          resolution 0.00670421
        }
        RotationalMotor {
          name "motor_wheel_left"
        }
      ]
      endPoint Solid {
        translation 0 0.094 0.0225
        rotation 0 0 0.9999999999999999 3.139727936715174
        children [
          Transform {
            scale 0.001 0.001 0.001
            children [
              Shape {
                appearance PBRAppearance {
                  baseColor 0.1 0.1 0.5
                  roughness 1
                  metalness 0
                }
                geometry Mesh {
                  url [
                    "../meshes/wheel.obj"
                  ]
                }
              }
            ]
          }
        ]
        name "wheel_left"
        boundingObject Transform {
          translation 0 -0.0125 0
          rotation 1 0 0 1.5708
          children [
            Shape {
              geometry Cylinder {
                height 0.025
                radius 0.038
              }
            }
          ]
        }
        physics Physics {
        }
      }
    }
    HingeJoint {
      jointParameters HingeJointParameters {
        axis 0 1 0
        anchor 0 -0.0925 0.0225
      }
      device [
        PositionSensor {
          name "encoder_wheel_right"
          noise 0.001
          resolution 0.00670421
        }
        RotationalMotor {
          name "motor_wheel_right"
        }
      ]
      endPoint Solid {
        translation 0 -0.094 0.0225
        rotation 0 1 0 0
        children [
          Transform {
            scale 0.001 0.001 0.001
            children [
              DEF WHEEL Shape {
                appearance PBRAppearance {
                  baseColor 0.1 0.1 0.5
                  roughness 1
                  metalness 0
                }
                geometry Mesh {
                  url [
                    "../meshes/wheel.obj"
                  ]
                }
              }
            ]
          }
        ]
        name "wheel_right"
        boundingObject Transform {
          translation 0 -0.0125 0
          rotation 1 0 0 1.5708
          children [
            Shape {
              geometry Cylinder {
                height 0.025
                radius 0.038
              }
            }
          ]
        }
        physics Physics {
        }
      }
    }
  ]
  name "lilbot"
  boundingObject Transform {
    scale 0.001 0.001 0.001
    children [
      USE BODY
    ]
  }
  physics Physics {
    centerOfMass [
      -0.01 0 0.02
    ]
  }
  controller "<extern>"
}
