#VRML_SIM R2022a utf8
WorldInfo {
}
Viewpoint {
  orientation -0.12237555886443298 0.03342208427176121 0.991920957977776 2.4494568356870547
  position 1.716278353706655 -1.4044127064264535 0.6255459881633715
}
TexturedBackground {
}
TexturedBackgroundLight {
}
RectangleArena {
  floorSize 10 10
  floorTileSize 1 1
  wallHeight 2
}
Robot {
  translation 0.00025645553343459776 -2.7734275414413243e-05 -6.661188695820247e-05
  rotation -0.017394834375972345 -0.930289217044516 -0.36641423606041007 0.003114309639357815
  children [
    DistanceSensor {
      translation 0.042 -0.02 0.123
      rotation 0 0 1 -0.524
      name "ds1"
      lookupTable [
        0 1020 0
        0.05 1020 0
        0.15 0 0
      ]
      numberOfRays 2
      aperture 1
    }
    DistanceSensor {
      translation 0.042 0.02 0.123
      rotation 0 0 1 0.5240000000000002
      name "ds0"
      lookupTable [
        0 1020 0
        0.05 1020 0
        0.15 0 0
      ]
      numberOfRays 2
      aperture 1
    }
    Transform {
      translation 0 0 0.019
      rotation -0.5773509358554485 0.5773489358556708 0.5773509358554485 -2.094395307179586
      scale 0.001 0.001 0.001
      children [
        HingeJoint {
          jointParameters HingeJointParameters {
            position 0.005124152675186142
            axis 0 1 0
            anchor 0 0 0.025
          }
          device [
            RotationalMotor {
              name "left_wheel_motor"
            }
          ]
          endPoint Solid {
            translation -0.00012810325627800366 0 3.2821103983574074e-07
            rotation 0 1 0 0.005124152675218561
            children [
              DEF WHEEL Transform {
                children [
                  Shape {
                    appearance PBRAppearance {
                      baseColor 0.1 0.1 0.4
                      roughness 1
                      metalness 0
                    }
                    geometry Mesh {
                      url [
                        "/home/jeffrey/ros2_dev_ws/src/little_bot/little_bot_3d_sim/meshes/left_wheel.stl"
                      ]
                    }
                  }
                ]
              }
            ]
            name "left_wheel"
            boundingObject USE WHEEL
            physics Physics {
            }
            linearVelocity 8.24403956675727e-11 1.247763592360072e-10 1.4449499845359156e-09
            angularVelocity 8.005395186188282e-09 8.921542382679169e-09 1.9556801322089626e-08
          }
        }
        HingeJoint {
          jointParameters HingeJointParameters {
            position -0.0008002873366503849
            axis 0 1 0
            anchor 0 0 0.025
          }
          device [
            RotationalMotor {
              name "right_wheel_motor"
            }
          ]
          endPoint Solid {
            translation 2.0007181280626845e-05 0 8.005747325484647e-09
            rotation 0 -1 0 0.0008002873364243282
            children [
              DEF WHEEL Transform {
                children [
                  Shape {
                    appearance PBRAppearance {
                      baseColor 0.1 0.1 0.4
                      roughness 1
                      metalness 0
                    }
                    geometry Mesh {
                      url [
                        "/home/jeffrey/ros2_dev_ws/src/little_bot/little_bot_3d_sim/meshes/right_wheel.stl"
                      ]
                    }
                  }
                ]
              }
            ]
            name "right_wheel"
            boundingObject USE WHEEL
            physics Physics {
            }
            linearVelocity -1.590485670589461e-09 2.7697777245647847e-09 -6.9458165843080505e-09
            angularVelocity 8.87980366894113e-09 8.930860010742658e-09 -3.551546318828753e-08
          }
        }
        DEF BODY Shape {
          appearance Appearance {
            material Material {
            }
          }
          geometry Mesh {
            url [
              "/home/jeffrey/ros2_dev_ws/src/little_bot/little_bot_3d_sim/meshes/base.stl"
            ]
          }
        }
      ]
    }
  ]
  boundingObject Transform {
    translation 0 0 0.019
    rotation -0.5773509358554485 0.5773489358556708 0.5773509358554485 -2.094395307179586
    scale 0.001 0.001 0.001
    children [
      USE BODY
    ]
  }
  physics Physics {
  }
  controller "<extern>"
  linearVelocity 1.4662637182355831e-09 -2.1118489748633154e-09 -9.859024218995284e-11
  angularVelocity 7.87077892908672e-09 9.74329677206651e-09 7.361618487653763e-08
}
